<sdf version='1.6'>
  <world name='default'>
    <light name='sun' type='directional'>
      <cast_shadows>1</cast_shadows>
      <pose frame=''>0 0 10 0 -0 0</pose>
      <diffuse>0.8 0.8 0.8 1</diffuse>
      <specular>0.1 0.1 0.1 1</specular>
      <attenuation>
        <range>1000</range>
        <constant>0.9</constant>
        <linear>0.01</linear>
        <quadratic>0.001</quadratic>
      </attenuation>
      <direction>-0.5 0.5 -1</direction>
    </light>
    <model name='ground_plane'>
      <static>1</static>
      <link name='link'>
        <collision name='collision'>
          <geometry>
            <plane>
              <normal>0 0 1</normal>
              <size>100 100</size>
            </plane>
          </geometry>
          <surface>
            <friction>
              <ode>
                <mu>100</mu>
                <mu2>50</mu2>
              </ode>
              <torsional>
                <ode/>
              </torsional>
            </friction>
            <contact>
              <ode/>
            </contact>
            <bounce/>
          </surface>
          <max_contacts>10</max_contacts>
        </collision>
        <visual name='visual'>
          <cast_shadows>0</cast_shadows>
          <geometry>
            <plane>
              <normal>0 0 1</normal>
              <size>100 100</size>
            </plane>
          </geometry>
          <material>
            <script>
              <uri>file://media/materials/scripts/gazebo.material</uri>
              <name>Gazebo/Grey</name>
            </script>
          </material>
        </visual>
        <self_collide>0</self_collide>
        <kinematic>0</kinematic>
      </link>
    </model>
    <gravity>0 0 -9.8</gravity>
    <magnetic_field>6e-06 2.3e-05 -4.2e-05</magnetic_field>
    <atmosphere type='adiabatic'/>
    <physics name='default_physics' default='0' type='ode'>
      <max_step_size>0.001</max_step_size>
      <real_time_factor>1</real_time_factor>
      <real_time_update_rate>1000</real_time_update_rate>
    </physics>
    <scene>
      <ambient>0.4 0.4 0.4 1</ambient>
      <background>0.7 0.7 0.7 1</background>
      <shadows>1</shadows>
    </scene>
    <spherical_coordinates>
      <surface_model>EARTH_WGS84</surface_model>
      <latitude_deg>0</latitude_deg>
      <longitude_deg>0</longitude_deg>
      <elevation>0</elevation>
      <heading_deg>0</heading_deg>
    </spherical_coordinates>
    <model name='racecar'>
      <link name='base_footprint'>
        <pose frame=''>0 0 0 0 -0 0</pose>
        <inertial>
          <pose frame=''>-0.006523 0 0.104076 0 -0 0</pose>
          <mass>3.798</mass>
          <inertia>
            <ixx>0.0152053</ixx>
            <ixy>0</ixy>
            <ixz>4.66806e-05</ixz>
            <iyy>0.0233094</iyy>
            <iyz>0</iyz>
            <izz>0.0331648</izz>
          </inertia>
        </inertial>
        <collision name='base_footprint_fixed_joint_lump__chassis_collision'>
          <pose frame=''>0 0 0.1025 0 -0 0</pose>
          <geometry>
            <box>
              <size>0.258 0.168 0.01</size>
            </box>
          </geometry>
          <surface>
            <contact>
              <ode/>
            </contact>
            <friction>
              <ode/>
              <torsional>
                <ode/>
              </torsional>
            </friction>
            <bounce/>
          </surface>
          <max_contacts>10</max_contacts>
        </collision>
        <collision name='base_footprint_fixed_joint_lump__left_battery_collision_1'>
          <pose frame=''>-0.025 0.057319 0.10802 0.349066 -0 0</pose>
          <geometry>
            <box>
              <size>0.16 0.047 0.024</size>
            </box>
          </geometry>
          <surface>
            <contact>
              <ode/>
            </contact>
            <friction>
              <ode/>
              <torsional>
                <ode/>
              </torsional>
            </friction>
            <bounce/>
          </surface>
          <max_contacts>10</max_contacts>
        </collision>
        <collision name='base_footprint_fixed_joint_lump__right_battery_collision_2'>
          <pose frame=''>-0.025 -0.057319 0.10802 -0.349066 0 0</pose>
          <geometry>
            <box>
              <size>0.16 0.047 0.024</size>
            </box>
          </geometry>
          <surface>
            <contact>
              <ode/>
            </contact>
            <friction>
              <ode/>
              <torsional>
                <ode/>
              </torsional>
            </friction>
            <bounce/>
          </surface>
          <max_contacts>10</max_contacts>
        </collision>
        <collision name='base_footprint_fixed_joint_lump__platform_link_collision_3'>
          <pose frame=''>0 0 0.1875 0 -0 0</pose>
          <geometry>
            <box>
              <size>0.4 0.18 0.01</size>
            </box>
          </geometry>
          <surface>
            <contact>
              <ode/>
            </contact>
            <friction>
              <ode/>
              <torsional>
                <ode/>
              </torsional>
            </friction>
            <bounce/>
          </surface>
          <max_contacts>10</max_contacts>
        </collision>
        <collision name='base_footprint_fixed_joint_lump__camera_link_collision_4'>
          <pose frame=''>0.16 0 0.2375 0 -0 0</pose>
          <geometry>
            <box>
              <size>0.03 0.16 0.03</size>
            </box>
          </geometry>
          <surface>
            <contact>
              <ode/>
            </contact>
            <friction>
              <ode/>
              <torsional>
                <ode/>
              </torsional>
            </friction>
            <bounce/>
          </surface>
          <max_contacts>10</max_contacts>
        </collision>
        <collision name='base_footprint_fixed_joint_lump__imu_link_collision_5'>
          <pose frame=''>0.16 0 0.2025 0 -0 0</pose>
          <geometry>
            <box>
              <size>0.04 0.04 0.03</size>
            </box>
          </geometry>
          <surface>
            <contact>
              <ode/>
            </contact>
            <friction>
              <ode/>
              <torsional>
                <ode/>
              </torsional>
            </friction>
            <bounce/>
          </surface>
          <max_contacts>10</max_contacts>
        </collision>
        <collision name='base_footprint_fixed_joint_lump__lidar_platform_link_collision_6'>
          <pose frame=''>0.08 0 0.2675 0 -0 0</pose>
          <geometry>
            <box>
              <size>0.12 0.1 0.01</size>
            </box>
          </geometry>
          <surface>
            <contact>
              <ode/>
            </contact>
            <friction>
              <ode/>
              <torsional>
                <ode/>
              </torsional>
            </friction>
            <bounce/>
          </surface>
          <max_contacts>10</max_contacts>
        </collision>
        <collision name='base_footprint_fixed_joint_lump__laser_link_collision_7'>
          <pose frame=''>0.08 0 0.2975 0 -0 0</pose>
          <geometry>
            <cylinder>
              <length>0.06</length>
              <radius>0.05</radius>
            </cylinder>
          </geometry>
          <surface>
            <contact>
              <ode/>
            </contact>
            <friction>
              <ode/>
              <torsional>
                <ode/>
              </torsional>
            </friction>
            <bounce/>
          </surface>
          <max_contacts>10</max_contacts>
        </collision>
        <visual name='base_footprint_fixed_joint_lump__base_link_visual'>
          <pose frame=''>0 0 0.1075 0 -0 0</pose>
          <geometry>
            <box>
              <size>0.01 0.01 0.01</size>
            </box>
          </geometry>
          <material>
            <script>
              <name>Gazebo/Grey</name>
              <uri>file://media/materials/scripts/gazebo.material</uri>
            </script>
          </material>
        </visual>
        <visual name='base_footprint_fixed_joint_lump__chassis_visual_1'>
          <pose frame=''>0 0 0.1025 0 -0 0</pose>
          <geometry>
            <box>
              <size>0.258 0.168 0.01</size>
            </box>
          </geometry>
          <material>
            <script>
              <name>Gazebo/Grey</name>
              <uri>file://media/materials/scripts/gazebo.material</uri>
            </script>
          </material>
        </visual>
        <visual name='base_footprint_fixed_joint_lump__left_battery_visual_2'>
          <pose frame=''>-0.025 0.057319 0.10802 0.349066 -0 0</pose>
          <geometry>
            <box>
              <size>0.16 0.047 0.024</size>
            </box>
          </geometry>
          <material>
            <script>
              <name>Gazebo/Blue</name>
              <uri>file://media/materials/scripts/gazebo.material</uri>
            </script>
          </material>
        </visual>
        <visual name='base_footprint_fixed_joint_lump__right_battery_visual_3'>
          <pose frame=''>-0.025 -0.057319 0.10802 -0.349066 0 0</pose>
          <geometry>
            <box>
              <size>0.16 0.047 0.024</size>
            </box>
          </geometry>
          <material>
            <script>
              <name>Gazebo/Blue</name>
              <uri>file://media/materials/scripts/gazebo.material</uri>
            </script>
          </material>
        </visual>
        <visual name='base_footprint_fixed_joint_lump__platform_link_visual_4'>
          <pose frame=''>0 0 0.1875 0 -0 0</pose>
          <geometry>
            <box>
              <size>0.4 0.18 0.01</size>
            </box>
          </geometry>
          <material>
            <script>
              <name>Gazebo/Orange</name>
              <uri>file://media/materials/scripts/gazebo.material</uri>
            </script>
          </material>
        </visual>
        <visual name='base_footprint_fixed_joint_lump__camera_link_visual_5'>
          <pose frame=''>0.16 0 0.2375 1.57 -0 1.57</pose>
          <geometry>
            <mesh>
              <scale>0.1 0.1 0.1</scale>
              <uri>/home/daipingan/racecar_final_ws/src/racecar/racecar_description/meshes/S1030-0315.dae</uri>
            </mesh>
          </geometry>
          <material>
            <script>
              <name>Gazebo/Black</name>
              <uri>file://media/materials/scripts/gazebo.material</uri>
            </script>
          </material>
        </visual>
        <visual name='base_footprint_fixed_joint_lump__imu_link_visual_6'>
          <pose frame=''>0.16 0 0.2025 0 -0 0</pose>
          <geometry>
            <box>
              <size>0.04 0.04 0.03</size>
            </box>
          </geometry>
          <material>
            <script>
              <name>Gazebo/Black</name>
              <uri>file://media/materials/scripts/gazebo.material</uri>
            </script>
          </material>
        </visual>
        <visual name='base_footprint_fixed_joint_lump__lidar_platform_link_visual_7'>
          <pose frame=''>0.08 0 0.2675 0 -0 0</pose>
          <geometry>
            <box>
              <size>0.12 0.1 0.01</size>
            </box>
          </geometry>
          <material>
            <script>
              <name>Gazebo/Orange</name>
              <uri>file://media/materials/scripts/gazebo.material</uri>
            </script>
          </material>
        </visual>
        <visual name='base_footprint_fixed_joint_lump__laser_link_visual_8'>
          <pose frame=''>0.08 0 0.2975 0 -0 0</pose>
          <geometry>
            <cylinder>
              <length>0.05</length>
              <radius>0.05</radius>
            </cylinder>
          </geometry>
          <material>
            <script>
              <name>Gazebo/Black</name>
              <uri>file://media/materials/scripts/gazebo.material</uri>
            </script>
          </material>
        </visual>
        <velocity_decay/>
        <velocity_decay/>
        <velocity_decay/>
        <velocity_decay/>
        <velocity_decay/>
        <velocity_decay/>
        <velocity_decay/>
        <sensor name='camera_node' type='camera'>
          <update_rate>30</update_rate>
          <camera name='head'>
            <horizontal_fov>1.39626</horizontal_fov>
            <image>
              <width>1280</width>
              <height>720</height>
              <format>R8G8B8</format>
            </image>
            <clip>
              <near>0.02</near>
              <far>300</far>
            </clip>
            <noise>
              <type>gaussian</type>
              <mean>0</mean>
              <stddev>0.007</stddev>
            </noise>
          </camera>
          <plugin name='gazebo_camera' filename='libgazebo_ros_camera.so'>
            <alwaysOn>true</alwaysOn>
            <updateRate>0.0</updateRate>
            <cameraName>/camera</cameraName>
            <imageTopicName>image_raw</imageTopicName>
            <cameraInfoTopicName>camera_info</cameraInfoTopicName>
            <frameName>camera_link</frameName>
            <hackBaseline>0.07</hackBaseline>
            <distortionK1>0.0</distortionK1>
            <distortionK2>0.0</distortionK2>
            <distortionK3>0.0</distortionK3>
            <distortionT1>0.0</distortionT1>
            <distortionT2>0.0</distortionT2>
            <robotNamespace>/</robotNamespace>
          </plugin>
          <pose frame=''>0.16 0 0.2375 0 -0 0</pose>
        </sensor>
        <velocity_decay/>
        <velocity_decay/>
        <sensor name='imu_sensor' type='imu'>
          <always_on>1</always_on>
          <update_rate>100</update_rate>
          <visualize>1</visualize>
          <topic>/imu_data</topic>
          <plugin name='imu_plugin' filename='libgazebo_ros_imu_sensor.so'>
            <topicName>/imu_data</topicName>
            <bodyName>imu_link</bodyName>
            <updateRateHZ>10.0</updateRateHZ>
            <gaussianNoise>0.0</gaussianNoise>
            <xyzOffset>0 0 0</xyzOffset>
            <rpyOffset>0 0 0</rpyOffset>
            <frameName>imu_link</frameName>
            <robotNamespace>/</robotNamespace>
          </plugin>
          <pose frame=''>0.16 0 0.2025 0 -0 0</pose>
        </sensor>
        <velocity_decay/>
        <gravity>1</gravity>
        <velocity_decay/>
        <gravity>1</gravity>
        <velocity_decay/>
        <self_collide>0</self_collide>
        <sensor name='ls01g' type='ray'>
          <visualize>0</visualize>
          <update_rate>10</update_rate>
          <ray>
            <scan>
              <horizontal>
                <samples>360</samples>
                <resolution>1</resolution>
                <min_angle>-3.14159</min_angle>
                <max_angle>3.14159</max_angle>
              </horizontal>
              <vertical>
                <samples>1</samples>
                <min_angle>0</min_angle>
                <max_angle>0</max_angle>
              </vertical>
            </scan>
            <range>
              <min>0.1</min>
              <max>8</max>
              <resolution>0.01</resolution>
            </range>
            <noise>
              <type>gaussian</type>
              <mean>0</mean>
              <stddev>0.01</stddev>
            </noise>
          </ray>
          <plugin name='gazebo_ls01g' filename='libgazebo_ros_laser.so'>
            <topicName>/scan</topicName>
            <frameName>laser_link</frameName>
            <robotNamespace>/</robotNamespace>
          </plugin>
          <pose frame=''>0.08 0 0.2975 0 -0 0</pose>
        </sensor>
        <kinematic>0</kinematic>
      </link>
      <link name='left_steering_link'>
        <pose frame=''>0.1675 0.1525 0.084 0 -0 0</pose>
        <inertial>
          <pose frame=''>0 0 0 0 -0 0</pose>
          <mass>0.001</mass>
          <inertia>
            <ixx>0.001</ixx>
            <ixy>0</ixy>
            <ixz>0</ixz>
            <iyy>0.001</iyy>
            <iyz>0</iyz>
            <izz>0.001</izz>
          </inertia>
        </inertial>
        <self_collide>0</self_collide>
        <kinematic>0</kinematic>
      </link>
      <joint name='left_front_shock' type='prismatic'>
        <child>left_steering_link</child>
        <parent>base_footprint</parent>
        <axis>
          <xyz>0 0 -1</xyz>
          <limit>
            <lower>-0.042</lower>
            <upper>0.042</upper>
            <effort>12.5106</effort>
            <velocity>1000</velocity>
          </limit>
          <dynamics>
            <spring_reference>0</spring_reference>
            <spring_stiffness>0</spring_stiffness>
          </dynamics>
          <use_parent_model_frame>1</use_parent_model_frame>
        </axis>
      </joint>
      <link name='left_front_axle_carrier'>
        <pose frame=''>0.1675 0.1525 0.084 0 -0 0</pose>
        <inertial>
          <pose frame=''>0 0 0 0 -0 0</pose>
          <mass>0.001</mass>
          <inertia>
            <ixx>0.001</ixx>
            <ixy>0</ixy>
            <ixz>0</ixz>
            <iyy>0.001</iyy>
            <iyz>0</iyz>
            <izz>0.001</izz>
          </inertia>
        </inertial>
        <self_collide>0</self_collide>
        <kinematic>0</kinematic>
      </link>
      <joint name='left_steering_joint' type='revolute'>
        <child>left_front_axle_carrier</child>
        <parent>left_steering_link</parent>
        <axis>
          <xyz>0 0 1</xyz>
          <limit>
            <lower>-0.785398</lower>
            <upper>0.785398</upper>
            <effort>0.5649</effort>
            <velocity>4.553</velocity>
          </limit>
          <dynamics>
            <spring_reference>0</spring_reference>
            <spring_stiffness>0</spring_stiffness>
          </dynamics>
          <use_parent_model_frame>1</use_parent_model_frame>
        </axis>
      </joint>
      <link name='left_front_wheel'>
        <pose frame=''>0.1675 0.1525 0.084 1.5708 -0 0</pose>
        <inertial>
          <pose frame=''>0 0 0 0 -0 0</pose>
          <mass>0.29</mass>
          <inertia>
            <ixx>0.000746466</ixx>
            <ixy>0</ixy>
            <ixz>0</ixz>
            <iyy>0.000746466</iyy>
            <iyz>0</iyz>
            <izz>0.00111094</izz>
          </inertia>
        </inertial>
        <collision name='left_front_wheel_collision'>
          <pose frame=''>0 -0 0 0 -0 0</pose>
          <geometry>
            <cylinder>
              <length>0.0889</length>
              <radius>0.073025</radius>
            </cylinder>
          </geometry>
          <surface>
            <contact>
              <ode/>
            </contact>
            <friction>
              <ode/>
              <torsional>
                <ode/>
              </torsional>
            </friction>
            <bounce/>
          </surface>
          <max_contacts>10</max_contacts>
        </collision>
        <visual name='left_front_wheel_visual'>
          <pose frame=''>0 -0 0 0 -0 0</pose>
          <geometry>
            <cylinder>
              <length>0.0889</length>
              <radius>0.073025</radius>
            </cylinder>
          </geometry>
          <material>
            <script>
              <name>Gazebo/Black</name>
              <uri>file://media/materials/scripts/gazebo.material</uri>
            </script>
          </material>
        </visual>
        <gravity>1</gravity>
        <velocity_decay/>
        <self_collide>0</self_collide>
        <kinematic>0</kinematic>
      </link>
      <joint name='left_front_axle' type='revolute'>
        <child>left_front_wheel</child>
        <parent>left_front_axle_carrier</parent>
        <axis>
          <xyz>0 1 0</xyz>
          <limit>
            <lower>-1e+16</lower>
            <upper>1e+16</upper>
          </limit>
          <dynamics>
            <spring_reference>0</spring_reference>
            <spring_stiffness>0</spring_stiffness>
          </dynamics>
          <use_parent_model_frame>1</use_parent_model_frame>
        </axis>
      </joint>
      <link name='left_rear_axle_carrier'>
        <pose frame=''>-0.1675 0.1525 0.084 0 -0 0</pose>
        <inertial>
          <pose frame=''>0 0 0 0 -0 0</pose>
          <mass>0.001</mass>
          <inertia>
            <ixx>0.001</ixx>
            <ixy>0</ixy>
            <ixz>0</ixz>
            <iyy>0.001</iyy>
            <iyz>0</iyz>
            <izz>0.001</izz>
          </inertia>
        </inertial>
        <self_collide>0</self_collide>
        <kinematic>0</kinematic>
      </link>
      <joint name='left_rear_shock' type='prismatic'>
        <child>left_rear_axle_carrier</child>
        <parent>base_footprint</parent>
        <axis>
          <xyz>0 0 -1</xyz>
          <limit>
            <lower>-0.042</lower>
            <upper>0.042</upper>
            <effort>12.5106</effort>
            <velocity>1000</velocity>
          </limit>
          <dynamics>
            <spring_reference>0</spring_reference>
            <spring_stiffness>0</spring_stiffness>
          </dynamics>
          <use_parent_model_frame>1</use_parent_model_frame>
        </axis>
      </joint>
      <link name='left_rear_wheel'>
        <pose frame=''>-0.1675 0.1525 0.084 1.5708 -0 0</pose>
        <inertial>
          <pose frame=''>0 0 0 0 -0 0</pose>
          <mass>0.29</mass>
          <inertia>
            <ixx>0.000746466</ixx>
            <ixy>0</ixy>
            <ixz>0</ixz>
            <iyy>0.000746466</iyy>
            <iyz>0</iyz>
            <izz>0.00111094</izz>
          </inertia>
        </inertial>
        <collision name='left_rear_wheel_collision'>
          <pose frame=''>0 -0 0 0 -0 0</pose>
          <geometry>
            <cylinder>
              <length>0.0889</length>
              <radius>0.073025</radius>
            </cylinder>
          </geometry>
          <surface>
            <contact>
              <ode/>
            </contact>
            <friction>
              <ode/>
              <torsional>
                <ode/>
              </torsional>
            </friction>
            <bounce/>
          </surface>
          <max_contacts>10</max_contacts>
        </collision>
        <visual name='left_rear_wheel_visual'>
          <pose frame=''>0 -0 0 0 -0 0</pose>
          <geometry>
            <cylinder>
              <length>0.0889</length>
              <radius>0.073025</radius>
            </cylinder>
          </geometry>
          <material>
            <script>
              <name>Gazebo/Black</name>
              <uri>file://media/materials/scripts/gazebo.material</uri>
            </script>
          </material>
        </visual>
        <gravity>1</gravity>
        <velocity_decay/>
        <self_collide>0</self_collide>
        <kinematic>0</kinematic>
      </link>
      <joint name='left_rear_axle' type='revolute'>
        <child>left_rear_wheel</child>
        <parent>left_rear_axle_carrier</parent>
        <axis>
          <xyz>0 1 0</xyz>
          <limit>
            <lower>-1e+16</lower>
            <upper>1e+16</upper>
          </limit>
          <dynamics>
            <spring_reference>0</spring_reference>
            <spring_stiffness>0</spring_stiffness>
          </dynamics>
          <use_parent_model_frame>1</use_parent_model_frame>
        </axis>
      </joint>
      <link name='right_steering_link'>
        <pose frame=''>0.1675 -0.1525 0.084 0 -0 0</pose>
        <inertial>
          <pose frame=''>0 0 0 0 -0 0</pose>
          <mass>0.001</mass>
          <inertia>
            <ixx>0.001</ixx>
            <ixy>0</ixy>
            <ixz>0</ixz>
            <iyy>0.001</iyy>
            <iyz>0</iyz>
            <izz>0.001</izz>
          </inertia>
        </inertial>
        <self_collide>0</self_collide>
        <kinematic>0</kinematic>
      </link>
      <joint name='right_front_shock' type='prismatic'>
        <child>right_steering_link</child>
        <parent>base_footprint</parent>
        <axis>
          <xyz>0 0 -1</xyz>
          <limit>
            <lower>-0.042</lower>
            <upper>0.042</upper>
            <effort>12.5106</effort>
            <velocity>1000</velocity>
          </limit>
          <dynamics>
            <spring_reference>0</spring_reference>
            <spring_stiffness>0</spring_stiffness>
          </dynamics>
          <use_parent_model_frame>1</use_parent_model_frame>
        </axis>
      </joint>
      <link name='right_front_axle_carrier'>
        <pose frame=''>0.1675 -0.1525 0.084 0 -0 0</pose>
        <inertial>
          <pose frame=''>0 0 0 0 -0 0</pose>
          <mass>0.001</mass>
          <inertia>
            <ixx>0.001</ixx>
            <ixy>0</ixy>
            <ixz>0</ixz>
            <iyy>0.001</iyy>
            <iyz>0</iyz>
            <izz>0.001</izz>
          </inertia>
        </inertial>
        <self_collide>0</self_collide>
        <kinematic>0</kinematic>
      </link>
      <joint name='right_steering_joint' type='revolute'>
        <child>right_front_axle_carrier</child>
        <parent>right_steering_link</parent>
        <axis>
          <xyz>0 0 1</xyz>
          <limit>
            <lower>-0.785398</lower>
            <upper>0.785398</upper>
            <effort>0.5649</effort>
            <velocity>4.553</velocity>
          </limit>
          <dynamics>
            <spring_reference>0</spring_reference>
            <spring_stiffness>0</spring_stiffness>
          </dynamics>
          <use_parent_model_frame>1</use_parent_model_frame>
        </axis>
      </joint>
      <link name='right_front_wheel'>
        <pose frame=''>0.1675 -0.1525 0.084 1.5708 -0 0</pose>
        <inertial>
          <pose frame=''>0 0 0 0 -0 0</pose>
          <mass>0.29</mass>
          <inertia>
            <ixx>0.000746466</ixx>
            <ixy>0</ixy>
            <ixz>0</ixz>
            <iyy>0.000746466</iyy>
            <iyz>0</iyz>
            <izz>0.00111094</izz>
          </inertia>
        </inertial>
        <collision name='right_front_wheel_collision'>
          <pose frame=''>0 0 0 0 -0 0</pose>
          <geometry>
            <cylinder>
              <length>0.0889</length>
              <radius>0.073025</radius>
            </cylinder>
          </geometry>
          <surface>
            <contact>
              <ode/>
            </contact>
            <friction>
              <ode/>
              <torsional>
                <ode/>
              </torsional>
            </friction>
            <bounce/>
          </surface>
          <max_contacts>10</max_contacts>
        </collision>
        <visual name='right_front_wheel_visual'>
          <pose frame=''>0 0 0 0 -0 0</pose>
          <geometry>
            <cylinder>
              <length>0.0889</length>
              <radius>0.073025</radius>
            </cylinder>
          </geometry>
          <material>
            <script>
              <name>Gazebo/Black</name>
              <uri>file://media/materials/scripts/gazebo.material</uri>
            </script>
          </material>
        </visual>
        <gravity>1</gravity>
        <velocity_decay/>
        <self_collide>0</self_collide>
        <kinematic>0</kinematic>
      </link>
      <joint name='right_front_axle' type='revolute'>
        <child>right_front_wheel</child>
        <parent>right_front_axle_carrier</parent>
        <axis>
          <xyz>0 1 0</xyz>
          <limit>
            <lower>-1e+16</lower>
            <upper>1e+16</upper>
          </limit>
          <dynamics>
            <spring_reference>0</spring_reference>
            <spring_stiffness>0</spring_stiffness>
          </dynamics>
          <use_parent_model_frame>1</use_parent_model_frame>
        </axis>
      </joint>
      <link name='right_rear_axle_carrier'>
        <pose frame=''>-0.1675 -0.1525 0.084 0 -0 0</pose>
        <inertial>
          <pose frame=''>0 0 0 0 -0 0</pose>
          <mass>0.001</mass>
          <inertia>
            <ixx>0.001</ixx>
            <ixy>0</ixy>
            <ixz>0</ixz>
            <iyy>0.001</iyy>
            <iyz>0</iyz>
            <izz>0.001</izz>
          </inertia>
        </inertial>
        <self_collide>0</self_collide>
        <kinematic>0</kinematic>
      </link>
      <joint name='right_rear_shock' type='prismatic'>
        <child>right_rear_axle_carrier</child>
        <parent>base_footprint</parent>
        <axis>
          <xyz>0 0 -1</xyz>
          <limit>
            <lower>-0.042</lower>
            <upper>0.042</upper>
            <effort>12.5106</effort>
            <velocity>1000</velocity>
          </limit>
          <dynamics>
            <spring_reference>0</spring_reference>
            <spring_stiffness>0</spring_stiffness>
          </dynamics>
          <use_parent_model_frame>1</use_parent_model_frame>
        </axis>
      </joint>
      <link name='right_rear_wheel'>
        <pose frame=''>-0.1675 -0.1525 0.084 1.5708 -0 0</pose>
        <inertial>
          <pose frame=''>0 0 0 0 -0 0</pose>
          <mass>0.29</mass>
          <inertia>
            <ixx>0.000746466</ixx>
            <ixy>0</ixy>
            <ixz>0</ixz>
            <iyy>0.000746466</iyy>
            <iyz>0</iyz>
            <izz>0.00111094</izz>
          </inertia>
        </inertial>
        <collision name='right_rear_wheel_collision'>
          <pose frame=''>0 0 0 0 -0 0</pose>
          <geometry>
            <cylinder>
              <length>0.0889</length>
              <radius>0.073025</radius>
            </cylinder>
          </geometry>
          <surface>
            <contact>
              <ode/>
            </contact>
            <friction>
              <ode/>
              <torsional>
                <ode/>
              </torsional>
            </friction>
            <bounce/>
          </surface>
          <max_contacts>10</max_contacts>
        </collision>
        <visual name='right_rear_wheel_visual'>
          <pose frame=''>0 0 0 0 -0 0</pose>
          <geometry>
            <cylinder>
              <length>0.0889</length>
              <radius>0.073025</radius>
            </cylinder>
          </geometry>
          <material>
            <script>
              <name>Gazebo/Black</name>
              <uri>file://media/materials/scripts/gazebo.material</uri>
            </script>
          </material>
        </visual>
        <gravity>1</gravity>
        <velocity_decay/>
        <self_collide>0</self_collide>
        <kinematic>0</kinematic>
      </link>
      <joint name='right_rear_axle' type='revolute'>
        <child>right_rear_wheel</child>
        <parent>right_rear_axle_carrier</parent>
        <axis>
          <xyz>0 1 0</xyz>
          <limit>
            <lower>-1e+16</lower>
            <upper>1e+16</upper>
          </limit>
          <dynamics>
            <spring_reference>0</spring_reference>
            <spring_stiffness>0</spring_stiffness>
          </dynamics>
          <use_parent_model_frame>1</use_parent_model_frame>
        </axis>
      </joint>
      <static>0</static>
      <plugin name='gazebo_ros_control' filename='libgazebo_ros_control.so'>
        <robotNamespace>/racecar</robotNamespace>
        <robotSimType>gazebo_ros_control/DefaultRobotHWSim</robotSimType>
        <legacyModeNS>true</legacyModeNS>
      </plugin>
      <pose frame=''>-0.5 0 0 0 -0 0</pose>
    </model>
    <model name='racetrack.word'>
      <pose frame=''>4.258 3.452 0 0 -0 0</pose>
      <link name='Wall_0'>
        <collision name='Wall_0_Collision'>
          <geometry>
            <box>
              <size>17.046 0.15 0.5</size>
            </box>
          </geometry>
          <pose frame=''>0 0 0.25 0 -0 0</pose>
          <max_contacts>10</max_contacts>
          <surface>
            <contact>
              <ode/>
            </contact>
            <bounce/>
            <friction>
              <torsional>
                <ode/>
              </torsional>
              <ode/>
            </friction>
          </surface>
        </collision>
        <visual name='Wall_0_Visual'>
          <pose frame=''>0 0 0.25 0 -0 0</pose>
          <geometry>
            <box>
              <size>17.046 0.15 0.5</size>
            </box>
          </geometry>
          <material>
            <script>
              <uri>file://media/materials/scripts/gazebo.material</uri>
              <name>Gazebo/Grey</name>
            </script>
            <ambient>1 1 1 1</ambient>
          </material>
          <meta>
            <layer>0</layer>
          </meta>
        </visual>
        <pose frame=''>0 -5.175 0 0 -0 0</pose>
        <self_collide>0</self_collide>
        <kinematic>0</kinematic>
      </link>
      <link name='Wall_11'>
        <collision name='Wall_11_Collision'>
          <geometry>
            <box>
              <size>6.00003 0.15 0.5</size>
            </box>
          </geometry>
          <pose frame=''>0 0 0.25 0 -0 0</pose>
          <max_contacts>10</max_contacts>
          <surface>
            <contact>
              <ode/>
            </contact>
            <bounce/>
            <friction>
              <torsional>
                <ode/>
              </torsional>
              <ode/>
            </friction>
          </surface>
        </collision>
        <visual name='Wall_11_Visual'>
          <pose frame=''>0 0 0.25 0 -0 0</pose>
          <geometry>
            <box>
              <size>6.00003 0.15 0.5</size>
            </box>
          </geometry>
          <material>
            <script>
              <uri>file://media/materials/scripts/gazebo.material</uri>
              <name>Gazebo/Grey</name>
            </script>
            <ambient>1 1 1 1</ambient>
          </material>
          <meta>
            <layer>0</layer>
          </meta>
        </visual>
        <pose frame=''>-5.684 0.065791 0 0 -0 1.5708</pose>
        <self_collide>0</self_collide>
        <kinematic>0</kinematic>
      </link>
      <link name='Wall_14'>
        <collision name='Wall_14_Collision'>
          <geometry>
            <box>
              <size>17 0.15 0.5</size>
            </box>
          </geometry>
          <pose frame=''>0 0 0.25 0 -0 0</pose>
          <max_contacts>10</max_contacts>
          <surface>
            <contact>
              <ode/>
            </contact>
            <bounce/>
            <friction>
              <torsional>
                <ode/>
              </torsional>
              <ode/>
            </friction>
          </surface>
        </collision>
        <visual name='Wall_14_Visual'>
          <pose frame=''>0 0 0.25 0 -0 0</pose>
          <geometry>
            <box>
              <size>17 0.15 0.5</size>
            </box>
          </geometry>
          <material>
            <script>
              <uri>file://media/materials/scripts/gazebo.material</uri>
              <name>Gazebo/Grey</name>
            </script>
            <ambient>1 1 1 1</ambient>
          </material>
          <meta>
            <layer>0</layer>
          </meta>
        </visual>
        <pose frame=''>-0.023 5.175 0 0 -0 0</pose>
        <self_collide>0</self_collide>
        <kinematic>0</kinematic>
      </link>
      <link name='Wall_17'>
        <collision name='Wall_17_Collision'>
          <geometry>
            <box>
              <size>10.5 0.15 0.5</size>
            </box>
          </geometry>
          <pose frame=''>0 0 0.25 0 -0 0</pose>
          <max_contacts>10</max_contacts>
          <surface>
            <contact>
              <ode/>
            </contact>
            <bounce/>
            <friction>
              <torsional>
                <ode/>
              </torsional>
              <ode/>
            </friction>
          </surface>
        </collision>
        <visual name='Wall_17_Visual'>
          <pose frame=''>0 0 0.25 0 -0 0</pose>
          <geometry>
            <box>
              <size>10.5 0.15 0.5</size>
            </box>
          </geometry>
          <material>
            <script>
              <uri>file://media/materials/scripts/gazebo.material</uri>
              <name>Gazebo/Grey</name>
            </script>
            <ambient>1 1 1 1</ambient>
          </material>
          <meta>
            <layer>0</layer>
          </meta>
        </visual>
        <pose frame=''>8.448 0 0 0 -0 1.5708</pose>
        <self_collide>0</self_collide>
        <kinematic>0</kinematic>
      </link>
      <link name='Wall_20'>
        <collision name='Wall_20_Collision'>
          <geometry>
            <box>
              <size>12.0597 0.15 0.5</size>
            </box>
          </geometry>
          <pose frame=''>0 0 0.25 0 -0 0</pose>
          <max_contacts>10</max_contacts>
          <surface>
            <contact>
              <ode/>
            </contact>
            <bounce/>
            <friction>
              <torsional>
                <ode/>
              </torsional>
              <ode/>
            </friction>
          </surface>
        </collision>
        <visual name='Wall_20_Visual'>
          <pose frame=''>0 0 0.25 0 -0 0</pose>
          <geometry>
            <box>
              <size>12.0597 0.15 0.5</size>
            </box>
          </geometry>
          <material>
            <script>
              <uri>file://media/materials/scripts/gazebo.material</uri>
              <name>Gazebo/Grey</name>
            </script>
            <ambient>1 1 1 1</ambient>
          </material>
          <meta>
            <layer>0</layer>
          </meta>
        </visual>
        <pose frame=''>0.250943 2.99079 0 0 -0 0</pose>
        <self_collide>0</self_collide>
        <kinematic>0</kinematic>
      </link>
      <link name='Wall_22'>
        <collision name='Wall_22_Collision'>
          <geometry>
            <box>
              <size>6 0.15 0.5</size>
            </box>
          </geometry>
          <pose frame=''>0 0 0.25 0 -0 0</pose>
          <max_contacts>10</max_contacts>
          <surface>
            <contact>
              <ode/>
            </contact>
            <bounce/>
            <friction>
              <torsional>
                <ode/>
              </torsional>
              <ode/>
            </friction>
          </surface>
        </collision>
        <visual name='Wall_22_Visual'>
          <pose frame=''>0 0 0.25 0 -0 0</pose>
          <geometry>
            <box>
              <size>6 0.15 0.5</size>
            </box>
          </geometry>
          <material>
            <script>
              <uri>file://media/materials/scripts/gazebo.material</uri>
              <name>Gazebo/Grey</name>
            </script>
            <ambient>1 1 1 1</ambient>
          </material>
          <meta>
            <layer>0</layer>
          </meta>
        </visual>
        <pose frame=''>6.18589 0.065791 0 0 -0 1.5708</pose>
        <self_collide>0</self_collide>
        <kinematic>0</kinematic>
      </link>
      <link name='Wall_7'>
        <collision name='Wall_7_Collision'>
          <geometry>
            <box>
              <size>10.5 0.15 0.5</size>
            </box>
          </geometry>
          <pose frame=''>0 0 0.25 0 -0 0</pose>
          <max_contacts>10</max_contacts>
          <surface>
            <contact>
              <ode/>
            </contact>
            <bounce/>
            <friction>
              <torsional>
                <ode/>
              </torsional>
              <ode/>
            </friction>
          </surface>
        </collision>
        <visual name='Wall_7_Visual'>
          <pose frame=''>0 0 0.25 0 -0 0</pose>
          <geometry>
            <box>
              <size>10.5 0.15 0.5</size>
            </box>
          </geometry>
          <material>
            <script>
              <uri>file://media/materials/scripts/gazebo.material</uri>
              <name>Gazebo/Grey</name>
            </script>
            <ambient>1 1 1 1</ambient>
          </material>
          <meta>
            <layer>0</layer>
          </meta>
        </visual>
        <pose frame=''>-8.448 0 0 0 -0 1.5708</pose>
        <self_collide>0</self_collide>
        <kinematic>0</kinematic>
      </link>
      <link name='Wall_9'>
        <collision name='Wall_9_Collision'>
          <geometry>
            <box>
              <size>12.0219 0.15 0.5</size>
            </box>
          </geometry>
          <pose frame=''>0 0 0.25 0 -0 0</pose>
          <max_contacts>10</max_contacts>
          <surface>
            <contact>
              <ode/>
            </contact>
            <bounce/>
            <friction>
              <torsional>
                <ode/>
              </torsional>
              <ode/>
            </friction>
          </surface>
        </collision>
        <visual name='Wall_9_Visual'>
          <pose frame=''>0 0 0.25 0 -0 0</pose>
          <geometry>
            <box>
              <size>12.0219 0.15 0.5</size>
            </box>
          </geometry>
          <material>
            <script>
              <uri>file://media/materials/scripts/gazebo.material</uri>
              <name>Gazebo/Grey</name>
            </script>
            <ambient>1 1 1 1</ambient>
          </material>
          <meta>
            <layer>0</layer>
          </meta>
        </visual>
        <pose frame=''>0.249943 -2.8626 0 0 -0 0.000572</pose>
        <self_collide>0</self_collide>
        <kinematic>0</kinematic>
      </link>
      <static>1</static>
    </model>
    <state world_name='default'>
      <sim_time>0 1000000</sim_time>
      <real_time>0 0</real_time>
      <wall_time>1597291434 327191368</wall_time>
      <iterations>1</iterations>
      <model name='ground_plane'>
        <pose frame=''>0 0 0 0 -0 0</pose>
        <scale>1 1 1</scale>
        <link name='link'>
          <pose frame=''>0 0 0 0 -0 0</pose>
          <velocity>0 0 0 0 -0 0</velocity>
          <acceleration>0 0 0 0 -0 0</acceleration>
          <wrench>0 0 0 0 -0 0</wrench>
        </link>
      </model>
      <model name='racecar'>
        <pose frame=''>-0.5 0 0 0 -0 0</pose>
        <scale>1 1 1</scale>
        <link name='base_footprint'>
          <pose frame=''>-0.5 0 0 0 -0 0</pose>
          <velocity>0 0 0 0 -0 0</velocity>
          <acceleration>-2.54168 -0.6344 1.62023 1.60533 0.614477 -1.89971</acceleration>
          <wrench>-9.65331 -2.40945 6.15365 0 -0 0</wrench>
        </link>
        <link name='left_front_axle_carrier'>
          <pose frame=''>-0.3325 0.1525 0.084 0 -0 0</pose>
          <velocity>0 0 0 0 -0 0</velocity>
          <acceleration>44.0669 -11.1123 -64.8596 0.078399 -1.48887 1.32271</acceleration>
          <wrench>0.044067 -0.011112 -0.06486 0 -0 0</wrench>
        </link>
        <link name='left_front_wheel'>
          <pose frame=''>-0.3325 0.1525 0.084 1.5708 -0 0</pose>
          <velocity>0 0 0 0 -0 0</velocity>
          <acceleration>33.3808 -8.84488 -34.7739 -2.52664 -1.02571 -0.010218</acceleration>
          <wrench>9.68044 -2.56501 -10.0844 0 -0 0</wrench>
        </link>
        <link name='left_rear_axle_carrier'>
          <pose frame=''>-0.6675 0.1525 0.084 0 -0 0</pose>
          <velocity>0 0 0 0 -0 0</velocity>
          <acceleration>57.7618 -13.291 43.7881 -0.032671 1.53132 -0.876993</acceleration>
          <wrench>0.057762 -0.013291 0.043788 0 -0 0</wrench>
        </link>
        <link name='left_rear_wheel'>
          <pose frame=''>-0.6675 0.1525 0.084 1.5708 -0 0</pose>
          <velocity>0 0 0 0 -0 0</velocity>
          <acceleration>35.581 -9.74076 0.92526 0.77029 -1.5031 3.01691</acceleration>
          <wrench>10.3185 -2.82482 0.268325 0 -0 0</wrench>
        </link>
        <link name='left_steering_link'>
          <pose frame=''>-0.3325 0.1525 0.084 0 -0 0</pose>
          <velocity>0 0 0 0 -0 0</velocity>
          <acceleration>18.3454 -5.38221 6.40942 -2.20327 0.204858 1.19102</acceleration>
          <wrench>0.018345 -0.005382 0.006409 0 -0 0</wrench>
        </link>
        <link name='right_front_axle_carrier'>
          <pose frame=''>-0.3325 -0.1525 0.084 0 -0 0</pose>
          <velocity>0 0 0 0 -0 0</velocity>
          <acceleration>12.3659 -5.17438 -64.5609 -2.92082 0.424691 -3.13115</acceleration>
          <wrench>0.012366 -0.005174 -0.064561 0 -0 0</wrench>
        </link>
        <link name='right_front_wheel'>
          <pose frame=''>-0.3325 -0.1525 0.084 1.5708 -0 0</pose>
          <velocity>0 0 0 0 -0 0</velocity>
          <acceleration>7.86013 -3.88136 -33.6592 -1.24232 0.124195 -2.56376</acceleration>
          <wrench>2.27944 -1.12559 -9.76118 0 -0 0</wrench>
        </link>
        <link name='right_rear_axle_carrier'>
          <pose frame=''>-0.6675 -0.1525 0.084 0 -0 0</pose>
          <velocity>0 0 0 0 -0 0</velocity>
          <acceleration>-48.7013 1.12175 -162.163 2.795 1.48087 -1.61259</acceleration>
          <wrench>-0.048701 0.001122 -0.162163 0 -0 0</wrench>
        </link>
        <link name='right_rear_wheel'>
          <pose frame=''>-0.6675 -0.1525 0.084 1.5708 -0 0</pose>
          <velocity>0 0 0 0 -0 0</velocity>
          <acceleration>67.365 -9.57148 -9.4639 1.15777 -1.33044 -1.03322</acceleration>
          <wrench>19.5359 -2.77573 -2.74453 0 -0 0</wrench>
        </link>
        <link name='right_steering_link'>
          <pose frame=''>-0.3325 -0.1525 0.084 0 -0 0</pose>
          <velocity>0 0 0 0 -0 0</velocity>
          <acceleration>1.41996 -1.92652 8.5139 -1.4039 0.798593 2.69448</acceleration>
          <wrench>0.00142 -0.001927 0.008514 0 -0 0</wrench>
        </link>
      </model>
      <model name='racetrack.word'>
        <pose frame=''>4.258 3.452 0 0 -0 0</pose>
        <scale>1 1 1</scale>
        <link name='Wall_0'>
          <pose frame=''>4.258 -1.723 0 0 -0 0</pose>
          <velocity>0 0 0 0 -0 0</velocity>
          <acceleration>0 0 0 0 -0 0</acceleration>
          <wrench>0 0 0 0 -0 0</wrench>
        </link>
        <link name='Wall_11'>
          <pose frame=''>-1.426 3.51779 0 0 -0 1.5708</pose>
          <velocity>0 0 0 0 -0 0</velocity>
          <acceleration>0 0 0 0 -0 0</acceleration>
          <wrench>0 0 0 0 -0 0</wrench>
        </link>
        <link name='Wall_14'>
          <pose frame=''>4.235 8.627 0 0 -0 0</pose>
          <velocity>0 0 0 0 -0 0</velocity>
          <acceleration>0 0 0 0 -0 0</acceleration>
          <wrench>0 0 0 0 -0 0</wrench>
        </link>
        <link name='Wall_17'>
          <pose frame=''>12.706 3.452 0 0 -0 1.5708</pose>
          <velocity>0 0 0 0 -0 0</velocity>
          <acceleration>0 0 0 0 -0 0</acceleration>
          <wrench>0 0 0 0 -0 0</wrench>
        </link>
        <link name='Wall_20'>
          <pose frame=''>4.50894 6.44279 0 0 -0 0</pose>
          <velocity>0 0 0 0 -0 0</velocity>
          <acceleration>0 0 0 0 -0 0</acceleration>
          <wrench>0 0 0 0 -0 0</wrench>
        </link>
        <link name='Wall_22'>
          <pose frame=''>10.4439 3.51779 0 0 -0 1.5708</pose>
          <velocity>0 0 0 0 -0 0</velocity>
          <acceleration>0 0 0 0 -0 0</acceleration>
          <wrench>0 0 0 0 -0 0</wrench>
        </link>
        <link name='Wall_7'>
          <pose frame=''>-4.19 3.452 0 0 -0 1.5708</pose>
          <velocity>0 0 0 0 -0 0</velocity>
          <acceleration>0 0 0 0 -0 0</acceleration>
          <wrench>0 0 0 0 -0 0</wrench>
        </link>
        <link name='Wall_9'>
          <pose frame=''>4.50794 0.5894 0 0 -0 0.000572</pose>
          <velocity>0 0 0 0 -0 0</velocity>
          <acceleration>0 0 0 0 -0 0</acceleration>
          <wrench>0 0 0 0 -0 0</wrench>
        </link>
      </model>
      <light name='sun'>
        <pose frame=''>0 0 10 0 -0 0</pose>
      </light>
    </state>
    <gui fullscreen='0'>
      <camera name='user_camera'>
        <pose frame=''>0.498405 -34.2025 44.1696 -0 0.839643 1.58019</pose>
        <view_controller>orbit</view_controller>
        <projection_type>perspective</projection_type>
      </camera>
    </gui>
  </world>
</sdf>
